2017-12-12 13:48:35,292 INFO: Microblog startup [in /Users/davidscroggins/Documents/GitHub/pyMegTut/app/__init__.py:45]
2017-12-12 13:48:56,091 ERROR: Exception on /edit_profile [POST] [in /Users/davidscroggins/anaconda2/envs/py36/lib/python3.6/site-packages/flask/app.py:1560]
Traceback (most recent call last):
  File "/Users/davidscroggins/anaconda2/envs/py36/lib/python3.6/site-packages/sqlalchemy/engine/base.py", line 1182, in _execute_context
    context)
  File "/Users/davidscroggins/anaconda2/envs/py36/lib/python3.6/site-packages/sqlalchemy/engine/default.py", line 470, in do_execute
    cursor.execute(statement, parameters)
sqlite3.IntegrityError: UNIQUE constraint failed: user.username

The above exception was the direct cause of the following exception:

Traceback (most recent call last):
  File "/Users/davidscroggins/anaconda2/envs/py36/lib/python3.6/site-packages/flask/app.py", line 1982, in wsgi_app
    response = self.full_dispatch_request()
  File "/Users/davidscroggins/anaconda2/envs/py36/lib/python3.6/site-packages/flask/app.py", line 1614, in full_dispatch_request
    rv = self.handle_user_exception(e)
  File "/Users/davidscroggins/anaconda2/envs/py36/lib/python3.6/site-packages/flask/app.py", line 1517, in handle_user_exception
    reraise(exc_type, exc_value, tb)
  File "/Users/davidscroggins/anaconda2/envs/py36/lib/python3.6/site-packages/flask/_compat.py", line 33, in reraise
    raise value
  File "/Users/davidscroggins/anaconda2/envs/py36/lib/python3.6/site-packages/flask/app.py", line 1612, in full_dispatch_request
    rv = self.dispatch_request()
  File "/Users/davidscroggins/anaconda2/envs/py36/lib/python3.6/site-packages/flask/app.py", line 1598, in dispatch_request
    return self.view_functions[rule.endpoint](**req.view_args)
  File "/Users/davidscroggins/anaconda2/envs/py36/lib/python3.6/site-packages/flask_login/utils.py", line 228, in decorated_view
    return func(*args, **kwargs)
  File "/Users/davidscroggins/Documents/GitHub/pyMegTut/app/routes.py", line 95, in edit_profile
    db.session.commit()
  File "/Users/davidscroggins/anaconda2/envs/py36/lib/python3.6/site-packages/sqlalchemy/orm/scoping.py", line 157, in do
    return getattr(self.registry(), name)(*args, **kwargs)
  File "/Users/davidscroggins/anaconda2/envs/py36/lib/python3.6/site-packages/sqlalchemy/orm/session.py", line 874, in commit
    self.transaction.commit()
  File "/Users/davidscroggins/anaconda2/envs/py36/lib/python3.6/site-packages/sqlalchemy/orm/session.py", line 461, in commit
    self._prepare_impl()
  File "/Users/davidscroggins/anaconda2/envs/py36/lib/python3.6/site-packages/sqlalchemy/orm/session.py", line 441, in _prepare_impl
    self.session.flush()
  File "/Users/davidscroggins/anaconda2/envs/py36/lib/python3.6/site-packages/sqlalchemy/orm/session.py", line 2139, in flush
    self._flush(objects)
  File "/Users/davidscroggins/anaconda2/envs/py36/lib/python3.6/site-packages/sqlalchemy/orm/session.py", line 2259, in _flush
    transaction.rollback(_capture_exception=True)
  File "/Users/davidscroggins/anaconda2/envs/py36/lib/python3.6/site-packages/sqlalchemy/util/langhelpers.py", line 66, in __exit__
    compat.reraise(exc_type, exc_value, exc_tb)
  File "/Users/davidscroggins/anaconda2/envs/py36/lib/python3.6/site-packages/sqlalchemy/util/compat.py", line 187, in reraise
    raise value
  File "/Users/davidscroggins/anaconda2/envs/py36/lib/python3.6/site-packages/sqlalchemy/orm/session.py", line 2223, in _flush
    flush_context.execute()
  File "/Users/davidscroggins/anaconda2/envs/py36/lib/python3.6/site-packages/sqlalchemy/orm/unitofwork.py", line 389, in execute
    rec.execute(self)
  File "/Users/davidscroggins/anaconda2/envs/py36/lib/python3.6/site-packages/sqlalchemy/orm/unitofwork.py", line 548, in execute
    uow
  File "/Users/davidscroggins/anaconda2/envs/py36/lib/python3.6/site-packages/sqlalchemy/orm/persistence.py", line 177, in save_obj
    mapper, table, update)
  File "/Users/davidscroggins/anaconda2/envs/py36/lib/python3.6/site-packages/sqlalchemy/orm/persistence.py", line 737, in _emit_update_statements
    execute(statement, multiparams)
  File "/Users/davidscroggins/anaconda2/envs/py36/lib/python3.6/site-packages/sqlalchemy/engine/base.py", line 945, in execute
    return meth(self, multiparams, params)
  File "/Users/davidscroggins/anaconda2/envs/py36/lib/python3.6/site-packages/sqlalchemy/sql/elements.py", line 263, in _execute_on_connection
    return connection._execute_clauseelement(self, multiparams, params)
  File "/Users/davidscroggins/anaconda2/envs/py36/lib/python3.6/site-packages/sqlalchemy/engine/base.py", line 1053, in _execute_clauseelement
    compiled_sql, distilled_params
  File "/Users/davidscroggins/anaconda2/envs/py36/lib/python3.6/site-packages/sqlalchemy/engine/base.py", line 1189, in _execute_context
    context)
  File "/Users/davidscroggins/anaconda2/envs/py36/lib/python3.6/site-packages/sqlalchemy/engine/base.py", line 1402, in _handle_dbapi_exception
    exc_info
  File "/Users/davidscroggins/anaconda2/envs/py36/lib/python3.6/site-packages/sqlalchemy/util/compat.py", line 203, in raise_from_cause
    reraise(type(exception), exception, tb=exc_tb, cause=cause)
  File "/Users/davidscroggins/anaconda2/envs/py36/lib/python3.6/site-packages/sqlalchemy/util/compat.py", line 186, in reraise
    raise value.with_traceback(tb)
  File "/Users/davidscroggins/anaconda2/envs/py36/lib/python3.6/site-packages/sqlalchemy/engine/base.py", line 1182, in _execute_context
    context)
  File "/Users/davidscroggins/anaconda2/envs/py36/lib/python3.6/site-packages/sqlalchemy/engine/default.py", line 470, in do_execute
    cursor.execute(statement, parameters)
sqlalchemy.exc.IntegrityError: (sqlite3.IntegrityError) UNIQUE constraint failed: user.username [SQL: 'UPDATE user SET username=?, about_me=? WHERE user.id = ?'] [parameters: ('bob', 'I am Susan. The first user of this app. I like cats.', 1)]
